Workbook

Sheet DELIVERY 2024 COST
A1: DATE | B1: ITEM CODE | C1: ITEM DESCRIPTION | D1: UOM | E1: DELIVERY | F1: D/N NO AND R/V NO | G1: UNIT PRICE
A2: 45294 | B2: 401101620001 | C2: Fibre Board (MDF) 4x8x 3mm - MD03 /HAVING MORTHAN 2 ITEM NO | D2: SHT | E2: 500 | F2: BBMC DN-24200011 | G2: =IFERROR(VLOOKUP(B2,'MAIN 0'!$A$2:$C$6861,3,0),0) -> 10.5
A3: 45297 | B3: 631101840005 | C3: Eps Sheet 244x122x10cm D-16-18K.g | D3: SHT | E3: 20 | F3: NPPF INV 2024-00023 | G3: =IFERROR(VLOOKUP(B3,'MAIN 0'!$A$2:$C$6861,3,0),0) -> 65.17
A4: 45297 | B4: 631101840006 | C4: Eps Sheet 244x122x3cm D-16-18K.g | D4: SHT | E4: 30 | F4: NPPF INV 2024-00023 | G4: =IFERROR(VLOOKUP(B4,'MAIN 0'!$A$2:$C$6861,3,0),0) -> 21.88
A5: 45299 | B5: 401101840442 | C5: STEEL TUBE 16X16X1.5MM | D5: Pcs | E5: 170 | F5: QATAR STEEL DN-67560 | G5: =IFERROR(VLOOKUP(B5,'MAIN 0'!$A$2:$C$6861,3,0),0) -> 12.25
A6: 45299 | B6: 401101840496 | C6: Rec.Angle Tube 40x20x1.5mm | D6: PCS | E6: 20 | F6: QATAR STEEL DN-67560 | G6: =IFERROR(VLOOKUP(B6,'MAIN 0'!$A$2:$C$6861,3,0),0) -> 22
A7: 45299 | B7: 401101840493 | C7: STEEL TUBE 19X19X1.5MM | D7: PCS | E7: 120 | F7: QATAR STEEL DN-67560 | G7: =IFERROR(VLOOKUP(B7,'MAIN 0'!$A$2:$C$6861,3,0),0) -> 14.9
A8: 45299 | B8: 401101840397 | C8: STEEL TUBE 30X30X1.5MM | D8: Pcs | E8: 70 | F8: QATAR STEEL DN-67560 | G8: =IFERROR(VLOOKUP(B8,'MAIN 0'!$A$2:$C$6861,3,0),0) -> 22.5
A9: 45299 | B9: 401101840406 | C9: Round Bar 8mm | D9: Pcs | E9: 600 | F9: AL ITTEFAQ INV 24-00495 | G9: =IFERROR(VLOOKUP(B9,'MAIN 0'!$A$2:$C$6861,3,0),0) -> 7.5
A10: 45300 | B10: 521101840011 | C10: G.I Pipe 2"X1.5mm | D10: DRM | E10: 36 | F10: QATAR STEEL DN-67586 | G10: =IFERROR(VLOOKUP(B10,'MAIN 0'!$A$2:$C$6861,3,0),0) -> 45
A11: 45300 | B11: 631101840005 | C11: Eps Sheet 244x122x10cm D-16-18K.g | D11: SHT | E11: 12 | F11: NPPF DN-00139 | G11: =IFERROR(VLOOKUP(B11,'MAIN 0'!$A$2:$C$6861,3,0),0) -> 65.17
A12: 45299 | B12: 401101840500 | C12: Double Side Tape1" 25mmX50Mtr - Star Tape - Ind | D12: PCS | E12: 72 | F12: UNISTAR DN-51690 | G12: =IFERROR(VLOOKUP(B12,'MAIN 0'!$A$2:$C$6861,3,0),0) -> 35
A13: 45301 | B13: 110310390023 | C13: GARBAGE BAGS BLACK 80 X 110 | D13: BDL | E13: 20 | F13: ORIENT PLASTIC DN-208846 | G13: =IFERROR(VLOOKUP(B13,'MAIN 0'!$A$2:$C$6861,3,0),0) -> 110
... A1228: 45631 | B1228: 401101840401 | C1228: STEEL PIPE 3cmx1.5mm | D1228: Pcs | E1228: 3 | F1228: AL ITTEFAQ DN-24-18845 | G1228: =IFERROR(VLOOKUP(B1228,'MAIN 0'!$A$2:$C$6861,3,0),0) -> 32

Sheet OLD
M1: STEEL FABRICATION
A2: DATE | B2: ITEM DESCRIPTION | C2: ITEM CODE | D2: DATE | E2: ITEM DESCRIPTION | F2: UOM | G2: COST | H2: D/N NO | I2: CATEGORY | J2: TYPE | M2: DATE OF DELIVERY | N2: ITEM DESCRIPTION | O2: UNIT PRICE | P2: QTY | Q2: TOTAL PRICE
A3: 45638 | B3: Grinding Disk 4.5" | C3: 091101840002 | D3: 45638 | E3: Grinding Disk 4.5" | F3: PCS | G3: 3.5 | H3: AL ABDULLA TRDG DN-22834 | I3: STEEL FABRICATION CON | J3: STEEL FABRICATION | M3: =IFERROR(VLOOKUP(N3,$B$3:$G$508,3,0),0) -> 0 | O3: =IFERROR(VLOOKUP(N3,$B$3:$G$508,6,0),0) -> 0 | Q3: =PRODUCT(O3,P3) -> 0
A4: 45636 | B4: STEEL TUBE 30X30X1.5MM | C4: 401101840397 | D4: 45636 | E4: STEEL TUBE 30X30X1.5MM | F4: Pcs | G4: 22.5 | H4: QATAR STEEL DN NO- 74734 INV NO-120808 | I4: STEEL FABRICATION | J4: STEEL FABRICATION | M4: =IFERROR(VLOOKUP(N4,$B$3:$G$508,3,0),0) -> 0 | O4: =IFERROR(VLOOKUP(N4,$B$3:$G$508,6,0),0) -> 0 | Q4: =PRODUCT(O4,P4) -> 0
A5: 45634 | B5: Rec.Angle Tube 40x20x1.5mm | C5: 401101840496 | D5: 45634 | E5: Rec.Angle Tube 40x20x1.5mm | F5: PCS | G5: 22 | H5: QATAR STEEL DN-74680 | I5: STEEL FABRICATION | J5: STEEL FABRICATION | M5: =IFERROR(VLOOKUP(N5,$B$3:$G$508,3,0),0) -> 0 | O5: =IFERROR(VLOOKUP(N5,$B$3:$G$508,6,0),0) -> 0 | Q5: =PRODUCT(O5,P5) -> 0
A6: 45634 | B6: STEEL TUBE 40X40X1.5MM | C6: 401101840413 | D6: 45634 | E6: STEEL TUBE 40X40X1.5MM | F6: Pcs | G6: 29.5 | H6: QATAR STEEL DN-74680 | I6: STEEL FABRICATION | J6: STEEL FABRICATION | M6: =IFERROR(VLOOKUP(N6,$B$3:$G$508,3,0),0) -> 0 | O6: =IFERROR(VLOOKUP(N6,$B$3:$G$508,6,0),0) -> 0 | Q6: =PRODUCT(O6,P6) -> 0
A7: 45631 | B7: STEEL PIPE 3cmx1.5mm | C7: 401101840401 | D7: 45631 | E7: STEEL PIPE 3cmx1.5mm | F7: Pcs | G7: 32 | H7: AL ITTEFAQ DN-24-18845 | I7: STEEL FABRICATION | J7: STEEL FABRICATION | M7: =IFERROR(VLOOKUP(N7,$B$3:$G$508,3,0),0) -> 0 | O7: =IFERROR(VLOOKUP(N7,$B$3:$G$508,6,0),0) -> 0 | Q7: =PRODUCT(O7,P7) -> 0
A8: 45630 | B8: G.I Pipe 1"- ½ X3X6m | C8: 521101840018 | D8: 45630 | E8: G.I Pipe 1"- ½ X3X6m | F8: PCS | G8: 66.75 | H8: QATAR STEEL DN-24604 | I8: STEEL FABRICATION | J8: STEEL FABRICATION | M8: =IFERROR(VLOOKUP(N8,$B$3:$G$508,3,0),0) -> 0 | O8: =IFERROR(VLOOKUP(N8,$B$3:$G$508,6,0),0) -> 0 | Q8: =PRODUCT(O8,P8) -> 0
A9: 45630 | B9: STEEL TUBE 16X16X1.5MM | C9: 401101840442 | D9: 45630 | E9: STEEL TUBE 16X16X1.5MM | F9: Pcs | G9: 12.25 | H9: QATAR STEEL DN-24604 | I9: STEEL FABRICATION | J9: STEEL FABRICATION | M9: =IFERROR(VLOOKUP(N9,$B$3:$G$508,3,0),0) -> 0 | O9: =IFERROR(VLOOKUP(N9,$B$3:$G$508,6,0),0) -> 0 | Q9: =PRODUCT(O9,P9) -> 0
A10: 45623 | B10: Hummer Flap Disc G-80 4.5" | C10: 601101840002 | D10: 45623 | E10: Hummer Flap Disc G-80 4.5" | F10: PCS | G10: 2.5 | H10: AL ABDULLA TRDG DN-22802 | I10: STEEL FABRICATION CON | J10: STEEL FABRICATION | M10: =IFERROR(VLOOKUP(N10,$B$3:$G$508,3,0),0) -> 0 | O10: =IFERROR(VLOOKUP(N10,$B$3:$G$508,6,0),0) -> 0 | Q10: =PRODUCT(O10,P10) -> 0
A11: 45623 | B11: Round Bar 8mm | C11: 401101840406 | D11: 45623 | E11: Round Bar 8mm | F11: Pcs | G11: 7.5 | H11: QATAR STEEL INV NO-120290 -120291 | I11: STEEL FABRICATION | J11: STEEL FABRICATION | M11: =IFERROR(VLOOKUP(N11,$B$3:$G$508,3,0),0) -> 0 | O11: =IFERROR(VLOOKUP(N11,$B$3:$G$508,6,0),0) -> 0 | Q11: =PRODUCT(O11,P11) -> 0
A12: 45620 | B12: STEEL TUBE 25X25X1.5MM | C12: 401101840396 | D12: 45620 | E12: STEEL TUBE 25X25X1.5MM | F12: Pcs | G12: 20 | H12: QATAR STEEL DN-76442 | I12: STEEL FABRICATION | J12: STEEL FABRICATION | M12: =IFERROR(VLOOKUP(N12,$B$3:$G$508,3,0),0) -> 0 | O12: =IFERROR(VLOOKUP(N12,$B$3:$G$508,6,0),0) -> 0 | Q12: =PRODUCT(O12,P12) -> 0
A13: 45619 | B13: Welding Electrode E6013 | C13: 1166 | D13: 45619 | E13: Welding Electrode E6013 | F13: Pkt | G13: 14 | H13: AL ABDULLA TRDG DN-22140 | I13: STEEL FABRICATION CON | J13: STEEL FABRICATION | M13: TOTAL PRICE | Q13: =SUM(Q3:Q12) -> 0
A14: 45612 | B14: Kingspor Grinding Disc 4.5" (111x6 mm ) | C14: 601101840003 | D14: 45612 | E14: Kingspor Grinding Disc 4.5" (111x6 mm ) | F14: PCS | G14: 4.5 | H14: AL BAHAR DN-15238 | I14: STEEL FABRICATION CON | J14: STEEL FABRICATION | M14: CARPENTER
A15: 45612 | B15: STEEL TUBE 19X19X1.5MM | C15: 401101840493 | D15: 45612 | E15: STEEL TUBE 19X19X1.5MM | F15: PCS | G15: 14.9 | H15: QATAR STEEL DN-76178 | I15: STEEL FABRICATION | J15: STEEL FABRICATION | M15: DATE OF DELIVERY | N15: ITEM DESCRIPTION | O15: UNIT PRICE | P15: QTY | Q15: TOTAL PRICE
A16: 45594 | B16: Cutting Disk 14" | C16: 091101840003 | D16: 45594 | E16: Cutting Disk 14" | F16: PCS | G16: 16 | H16: AL ABDULLA TRDG DN-21971 | I16: STEEL FABRICATION CON | J16: STEEL FABRICATION | M16: =IFERROR(VLOOKUP(N16,$B$3:$G$508,3,0),0) -> 0 | O16: =IFERROR(VLOOKUP(N16,$B$3:$G$246,6,0),0) -> 0 | Q16: =PRODUCT(O16,P16) -> 0
A17: 45571 | B17: Flat Bar 40x4x6mtr | C17: 521101840016 | D17: 45571 | E17: Flat Bar 40x4x6mtr | F17: PCS | G17: 22.5 | H17: QATAR STEEL INV 37153 | I17: STEEL FABRICATION | J17: STEEL FABRICATION | M17: =IFERROR(VLOOKUP(N17,$B$3:$G$508,3,0),0) -> 0 | O17: =IFERROR(VLOOKUP(N17,$B$3:$G$246,6,0),0) -> 0 | Q17: =PRODUCT(O17,P17) -> 0
A18: 45556 | B18: G.I Pipe 4"X2mmX6m | C18: 521101840015 | D18: 45556 | E18: G.I Pipe 4"X2mmX6m | F18: PCS | G18: 106 | H18: QATAR STEEL INV 499698 AND 499699 | I18: STEEL FABRICATION | J18: STEEL FABRICATION | M18: =IFERROR(VLOOKUP(N18,$B$3:$G$508,3,0),0) -> 0 | O18: =IFERROR(VLOOKUP(N18,$B$3:$G$246,6,0),0) -> 0 | Q18: =PRODUCT(O18,P18) -> 0
A19: 45554 | B19: Concrete Drill Bit 6mmX110 | C19: 621101840006 | D19: 45554 | E19: Concrete Drill Bit 6mmX110 | F19: PCS | G19: 6 | H19: AL BAHAR DN-15009 | I19: STEEL FABRICATION CON | J19: STEEL FABRICATION | M19: =IFERROR(VLOOKUP(N19,$B$3:$G$508,3,0),0) -> 0 | O19: =IFERROR(VLOOKUP(N19,$B$3:$G$246,6,0),0) -> 0 | Q19: =PRODUCT(O19,P19) -> 0
A20: 45551 | B20: Round Bar 12mmX6mtr | C20: 521101840012 | D20: 45551 | E20: Round Bar 12mmX6mtr | F20: PCS | G20: 17.5 | H20: AL ITTEFAQ TRDG INV 13830 | I20: STEEL FABRICATION | J20: STEEL FABRICATION | M20: =IFERROR(VLOOKUP(N20,$B$3:$G$508,3,0),0) -> 0 | O20: =IFERROR(VLOOKUP(N20,$B$3:$G$246,6,0),0) -> 0 | Q20: =PRODUCT(O20,P20) -> 0
A21: 45533 | B21: G.I Pipe ½"X2mmX6m | C21: 521101840014 | D21: 45533 | E21: G.I Pipe ½"X2mmX6m | F21: PCS | G21: 23 | H21: AL - ITTEFAQ STEEL INV NO-12991 | I21: STEEL FABRICATION | J21: STEEL FABRICATION | M21: =IFERROR(VLOOKUP(N21,$B$3:$G$508,3,0),0) -> 0 | O21: =IFERROR(VLOOKUP(N21,$B$3:$G$246,6,0),0) -> 0 | Q21: =PRODUCT(O21,P21) -> 0
A22: 45533 | B22: STEEL TUBE 50X50X2MM | C22: 401101840412 | D22: 45533 | E22: STEEL TUBE 50X50X2MM | F22: Pcs | G22: 40.5 | H22: QATAR STEEL INV NO- 495936 | I22: STEEL FABRICATION | J22: STEEL FABRICATION | M22: =IFERROR(VLOOKUP(N22,$B$3:$G$508,3,0),0) -> 0 | O22: =IFERROR(VLOOKUP(N22,$B$3:$G$246,6,0),0) -> 0 | Q22: =PRODUCT(O22,P22) -> 0
A23: 45500 | B23: MS Tube 50X50X2.0mm | C23: 521101840009 | D23: 45500 | E23: MS Tube 50X50X2.0mm | F23: PCS | G23: 54 | H23: Qatar Steel DN N0 - 71811 | I23: STEEL FABRICATION | J23: STEEL FABRICATION | M23: =IFERROR(VLOOKUP(N23,$B$3:$G$508,3,0),0) -> 0 | O23: =IFERROR(VLOOKUP(N23,$B$3:$G$246,6,0),0) -> 0 | Q23: =PRODUCT(O23,P23) -> 0
A24: 45486 | B24: Rec.Angle Tube 50x25x1.5mm | C24: 401101840516 | D24: 45486 | E24: Rec.Angle Tube 50x25x1.5mm | F24: PCS | G24: 30.2 | H24: QATAR STEEL DN NO- 71517 | I24: STEEL FABRICATION | J24: STEEL FABRICATION | M24: =IFERROR(VLOOKUP(N24,$B$3:$G$508,3,0),0) -> 0 | O24: =IFERROR(VLOOKUP(N24,$B$3:$G$246,6,0),0) -> 0 | Q24: =PRODUCT(O24,P24) -> 0
A25: 45484 | B25: Cutting Disk 9 " | C25: 091101840001 | D25: 45484 | E25: Cutting Disk 9 " | F25: PCS | G25: 7 | H25: AL- ABDULLA TRD&CO. DN NO- 21739 | I25: STEEL FABRICATION CON | J25: STEEL FABRICATION | M25: =IFERROR(VLOOKUP(N25,$B$3:$G$508,3,0),0) -> 0 | O25: =IFERROR(VLOOKUP(N25,$B$3:$G$246,6,0),0) -> 0 | Q25: =PRODUCT(O25,P25) -> 0
A26: 45470 | B26: Steel Flat Bar 16X3mm | C26: 401101840453 | D26: 45470 | E26: Steel Flat Bar 16X3mm | F26: PCS | G26: 9 | H26: AL ITEFAQ STEEL INV -09851 | I26: STEEL FABRICATION | J26: STEEL FABRICATION | M26: TOTAL PRICE | Q26: =SUM(Q16:Q25) -> 0
A27: 45437 | B27: Round Bar 10mm | C27: 401101840475 | D27: 45437 | E27: Round Bar 10mm | F27: Pcs | G27: 15 | H27: AL ITTEFAQ INV 24-08196 | I27: STEEL FABRICATION | J27: STEEL FABRICATION | M27: FOAM AND ACRYLIC AND FOREX WORK
A28: 45428 | B28: Steel Tube 12x12x1.2mm | C28: 401101840452 | D28: 45428 | E28: Steel Tube 12x12x1.2mm | F28: PCS | G28: 10 | H28: AL ITTEFAQ INV 24-07674 | I28: STEEL FABRICATION | J28: STEEL FABRICATION | M28: DATE OF DELIVERY | N28: ITEM DESCRIPTION | O28: UNIT PRICE | P28: QTY | Q28: TOTAL PRICE
A29: 45428 | B29: Hand Glows Leather Full Sleave HD | C29: 571101840001 | D29: 45428 | E29: Hand Glows Leather Full Sleave HD | F29: PAIR | G29: 10 | H29: AL ABDULLA TRDG DN-20485 | I29: STEEL FABRICATION CON | J29: STEEL FABRICATION | M29: =IFERROR(VLOOKUP(N29,$B$3:$G$508,3,0),0) -> 0 | O29: =IFERROR(VLOOKUP(N29,$B$3:$G$246,6,0),0) -> 0 | Q29: =PRODUCT(O29,P29) -> 0
A30: 45409 | B30: Hand Glows Leather - HG1101 | C30: 401131910006 | D30: 45409 | E30: Hand Glows Leather - HG1101 | F30: PAR | G30: 3.8 | H30: AL-ABDULLA TRD.CO. DN NO- 20714 | I30: STEEL FABRICATION CON | J30: STEEL FABRICATION | M30: =IFERROR(VLOOKUP(N30,$B$3:$G$508,3,0),0) -> 0 | O30: =IFERROR(VLOOKUP(N30,$B$3:$G$246,6,0),0) -> 0 | Q30: =PRODUCT(O30,P30) -> 0
A31: 45383 | B31: Flat Bar 16x8x6m | C31: 521101840006 | D31: 45383 | E31: Flat Bar 16x8x6m | F31: PCS | G31: 24 | H31: AL ITTEFAQ INV 24-05316 | I31: STEEL FABRICATION | J31: STEEL FABRICATION | M31: =IFERROR(VLOOKUP(N31,$B$3:$G$508,3,0),0) -> 0 | O31: =IFERROR(VLOOKUP(N31,$B$3:$G$246,6,0),0) -> 0 | Q31: =PRODUCT(O31,P31) -> 0
A32: 45383 | B32: GI PIPE 1"X2MM - 6MTR | C32: 521101840002 | D32: 45383 | E32: GI PIPE 1"X2MM - 6MTR | F32: PCS | G32: 40 | H32: AL ITTEFAQ INV 24-05316 | I32: STEEL FABRICATION | J32: STEEL FABRICATION | M32: =IFERROR(VLOOKUP(N32,$B$3:$G$508,3,0),0) -> 0 | O32: =IFERROR(VLOOKUP(N32,$B$3:$G$246,6,0),0) -> 0 | Q32: =PRODUCT(O32,P32) -> 0
A33: 45307 | B33: Makita Cutting Disc 4.5" (115x1.2mm) | C33: 601101840001 | D33: 45307 | E33: Makita Cutting Disc 4.5" (115x1.2mm) | F33: PCS | G33: 3 | H33: AL BAHAR DN-13436 | I33: STEEL FABRICATION CON | J33: STEEL FABRICATION | M33: =IFERROR(VLOOKUP(N33,$B$3:$G$508,3,0),0) -> 0 | O33: =IFERROR(VLOOKUP(N33,$B$3:$G$246,6,0),0) -> 0 | Q33: =PRODUCT(O33,P33) -> 0
A34: 45305 | B34: STEEL PIPE ¾"x1.5mm | C34: 401101840441 | D34: 45305 | E34: STEEL PIPE ¾"x1.5mm | F34: Pcs | G34: 20 | H34: QATAR STEEL DN-67716 | I34: STEEL FABRICATION | J34: STEEL FABRICATION | M34: =IFERROR(VLOOKUP(N34,$B$3:$G$508,3,0),0) -> 0 | O34: =IFERROR(VLOOKUP(N34,$B$3:$G$246,6,0),0) -> 0 | Q34: =PRODUCT(O34,P34) -> 0
A35: 45300 | B35: G.I Pipe 2"X1.5mm | C35: 521101840011 | D35: 45300 | E35: G.I Pipe 2"X1.5mm | F35: DRM | G35: 45 | H35: QATAR STEEL DN-67586 | I35: STEEL FABRICATION | J35: STEEL FABRICATION | M35: =IFERROR(VLOOKUP(N35,$B$3:$G$508,3,0),0) -> 0 | O35: =IFERROR(VLOOKUP(N35,$B$3:$G$246,6,0),0) -> 0 | Q35: =PRODUCT(O35,P35) -> 0
A36: 45638 | B36: Screw 3" x8 black - (250/300 Pkt) | C36: 401101840025 | D36: 45638 | E36: Screw 3" x8 black - (250/300 Pkt) | F36: PKT | G36: 17.5 | H36: AL ABDULLA TRDG DN-22834 | I36: CARPENTER CON | J36: CARPENTER | M36: =IFERROR(VLOOKUP(N36,$B$3:$G$508,3,0),0) -> 0 | O36: =IFERROR(VLOOKUP(N36,$B$3:$G$246,6,0),0) -> 0 | Q36: =PRODUCT(O36,P36) -> 0
A37: 45638 | B37: Brad Nail Billionaire - F 20 (5000/Pkt) | C37: 581101840004 | D37: 45638 | E37: Brad Nail Billionaire - F 20 (5000/Pkt) | F37: PKT | G37: 12 | H37: AL ABDULLA TRDG DN-22834 | I37: CARPENTER CON | J37: CARPENTER | M37: =IFERROR(VLOOKUP(N37,$B$3:$G$508,3,0),0) -> 0 | O37: =IFERROR(VLOOKUP(N37,$B$3:$G$246,6,0),0) -> 0 | Q37: =PRODUCT(O37,P37) -> 0
A38: 45636 | B38: Makita Hss Dril Bit 4mm | C38: 401101910004 | D38: 45636 | E38: Makita Hss Dril Bit 4mm | F38: PCS | G38: 2.75 | H38: AL ABDUULLA DN NO- 22831 | I38: CARPENTER CON | J38: CARPENTER | M38: =IFERROR(VLOOKUP(N38,$B$3:$G$508,3,0),0) -> 0 | O38: =IFERROR(VLOOKUP(N38,$B$3:$G$246,6,0),0) -> 0 | Q38: =PRODUCT(O38,P38) -> 0
A39: 45636 | B39: STEEL SCREW HEX WASHER HEAD 4X14 | C39: 401101840450 | D39: 45636 | E39: STEEL SCREW HEX WASHER HEAD 4X14 | F39: PCS | G39: 46 | H39: AL ABDUULLA DN NO- 22831 | I39: CARPENTER CON | J39: CARPENTER | M39: TOTAL PRICE | Q39: =SUM(Q29:Q38) -> 0
A40: 45636 | B40: Exwell N3 Silicone Sealant | C40: 401101840528 | D40: 45636 | E40: Exwell N3 Silicone Sealant | F40: PCS | G40: 13.33 | H40: AL BAHAR DN NO-16042 | I40: CARPENTER CON | J40: CARPENTER | M40: GENERAL WORK
...

Sheet WORK  
A1: STEEL FABRICATION MATERIALS
A2: DATE | B2: ITEM DESCRIPTION | C2: UOM | D2: APPROXIMATE COST | E2: SUPPLIER
A3: 45636 | B3: STEEL TUBE 30X30X1.5MM | C3: Pcs | D3: 22.5 | E3: QATAR STEEL , AL ITTEFAQ
A4: 45634 | B4: Rec.Angle Tube 40x20x1.5mm | C4: PCS | D4: 22 | E4: QATAR STEEL , AL ITTEFAQ
A5: 45634 | B5: STEEL TUBE 40X40X1.5MM | C5: Pcs | D5: 29.5 | E5: QATAR STEEL , AL ITTEFAQ
A6: 45631 | B6: STEEL PIPE 3cmx1.5mm | C6: Pcs | D6: 32 | E6: QATAR STEEL , AL ITTEFAQ
A7: 45630 | B7: G.I Pipe 1"- ½ X3X6m | C7: PCS | D7: 66.75 | E7: QATAR STEEL , AL ITTEFAQ
A8: 45630 | B8: STEEL TUBE 16X16X1.5MM | C8: Pcs | D8: 12.25 | E8: QATAR STEEL , AL ITTEFAQ
A9: 45623 | B9: Round Bar 8mm | C9: Pcs | D9: 7.5 | E9: QATAR STEEL , AL ITTEFAQ
A10: 45620 | B10: STEEL TUBE 25X25X1.5MM | C10: Pcs | D10: 20 | E10: QATAR STEEL , AL ITTEFAQ
A11: 45612 | B11: STEEL TUBE 19X19X1.5MM | C11: PCS | D11: 14.9 | E11: QATAR STEEL , AL ITTEFAQ
A12: 45571 | B12: Flat Bar 40x4x6mtr | C12: PCS | D12: 22.5 | E12: QATAR STEEL , AL ITTEFAQ
A13: 45556 | B13: G.I Pipe 4"X2mmX6m | C13: PCS | D13: 106 | E13: QATAR STEEL , AL ITTEFAQ
A14: 45551 | B14: Round Bar 12mmX6mtr | C14: PCS | D14: 17.5 | E14: QATAR STEEL , AL ITTEFAQ
... A34: 45307 | B34: Makita Cutting Disc 4.5" (115x1.2mm) | C34: PCS | D34: 3 | E34: AL ABDULLA TRDG , AL BAHAR
A35: CARPENTER MATERIALS
B36: ITEM DESCRIPTION | C36: UOM | D36: APPROXIMATE COST | E36: SUPPLIER
A37: 45635 | B37: Commercial Plywood 4x8x9mm - Malaysia - KP09 | C37: SHT | D37: 45 | E37: BBMC , GRAND STORE
A38: 45633 | B38: Fibre Board(MDF) - 4x8x12MM - MD12 | C38: SHT | D38: 39 | E38: BBMC , GRAND STORE
A39: 45633 | B39: Fibre Board(MDF) - 4x8x6MM - MD06 | C39: SHT | D39: 20 | E39: BBMC , GRAND STORE
A40: 45627 | B40: Austrian White Wood -morabaa- 2x2x13 - AW22 | C40: Pcs | D40: 11 | E40: BBMC , GRAND STORE
A41: 45602 | B41: Fibre Board (MDF) 16MM | C41: SHT | D41: 46 | E41: BBMC , GRAND STORE
A42: 45601 | B42: Fibre Board (MDF) 4x8x 9mm - MD09 | C42: SHT | D42: 28 | E42: BBMC , GRAND STORE
A43: 45594 | B43: Polycarbonate Sheet clear Obscure 2.5mm | C43: SHT | D43: 350 | E43: SABIN PLASTIC , WORLD OF MATERIALS
A44: 45546 | B44: Plain MDF Board - 9mm Malaysia - MD09 | C44: SHT | D44: 30 | E44: BBMC , GRAND STORE
A45: 45497 | B45: Jumbo MDF 6x12x12mm | C45: SHT | D45: 115 | E45: BBMC , GRAND STORE
A46: 45481 | B46: 2x4x4Mtr White Wood - Austria | C46: PCS | D46: 21 | E46: BBMC , GRAND STORE
A47: 45481 | B47: Commercial Plywood 4x8x6mm - Indonesia KP07 | C47: SHT | D47: 26 | E47: BBMC , GRAND STORE
A48: 45475 | B48: Fibre Board (MDF) 4x8x 3mm - MD03 | C48: SHT | D48: 10.5 | E48: BBMC , GRAND STORE
... A126: 45300 | B126: Wood Nails 1" | C126: PKT | D126: 2.19 | E126: AL ABDULLA , AL BAHAR
A127: FOAM AND ACRYLIC AND FOREX WORK MATERIALS
B128: ITEM DESCRIPTION | C128: UOM | D128: APPROXIMATE COST | E128: SUPPLIER
A129: 45619 | B129: Forex Sheet White 2mm | C129: Sht | D129: 19 | E129: SABIN PLASTIC , WORLD OF MATERIALS
A130: 45619 | B130: Forex Sheet White 1mm | C130: SHT | D130: 15 | E130: SABIN PLASTIC , WORLD OF MATERIALS
A131: 45615 | B131: Acrylic Silver Mirror 122x244 - 2mm | C131: SHT | D131: 135 | E131: SABIN PLASTIC , WORLD OF MATERIALS
A132: 45594 | B132: Acrylic 122 X 240 X 2.0mm Black | C132: SHT | D132: 110 | E132: SABIN PLASTIC , WORLD OF MATERIALS
A133: 45584 | B133: Forex Sheet White 4mm | C133: SHT | D133: 34 | E133: SABIN PLASTIC , WORLD OF MATERIALS
A134: 45584 | B134: Forex sheet white 3mm | C134: SHT | D134: 26 | E134: SABIN PLASTIC , WORLD OF MATERIALS
A135: 45549 | B135: Eps Sheet 244x122x3cm D-16-18K.g | C135: SHT | D135: 21.88 | E135: NAFA, NATIONAL POLYSTYRENE PRODUCTS FACTORY QATAR
A136: 45533 | B136: Eps Sheet 244x122x5cm | C136: PCS | D136: 31.5 | E136: NAFA, NATIONAL POLYSTYRENE PRODUCTS FACTORY QATAR
...

Sheet MAIN WITH ITEM CODE 0
A1: DATE | B1: ITEM CODE | C1: DATE | D1: ITEM DESCRIPTION | E1: UOM | F1: DELIVERY | G1: COST | H1: D/N NO AND R/V NO
A2: 45638 | B2: 401101840025 | C2: 45638 | D2: Screw 3" x8 black - (250/300 Pkt) | E2: PKT | F2: 200 | G2: 17.5 | H2: AL ABDULLA TRDG DN-22834
A3: 45638 | B3: 091101840002 | C3: 45638 | D3: Grinding Disk 4.5" (CUTTING DISC 4.5") | E3: PCS | F3: 100 | G3: 3.5 | H3: AL ABDULLA TRDG DN-22834
A4: 45638 | B4: 401101840296 | C4: 45638 | D4: Abrasive paper (SAND PAPER) - 320 Korea | E4: Pcs | F4: 100 | G4: 0.9 | H4: AL ABDULLA TRDG DN-22834
A5: 45638 | B5: 401101840019 | C5: 45638 | D5: Mini paint roller 4" Refiller | E5: PCS | F5: 170 | G5: 1.5 | H5: AL ABDULLA TRDG DN-22834
A6: 45638 | B6: 401101840006 | C6: 45638 | D6: Hand brush 2" /HAVING MORTHAN 2 ITEM NO | E6: PCS | F6: 12 | G6: 3.5 | H6: AL ABDULLA TRDG DN-22834
A7: 45638 | B7: 401101840131 | C7: 45638 | D7: Hand Brush Petta - 1" - Oryx /HAVING MORTHAN 2 ITEM NO | E7: PCS | F7: 12 | G7: 3 | H7: AL ABDULLA TRDG DN-22834
A8: 45638 | B8: 581101840004 | C8: 45638 | D8: Brad Nail Billionaire - F 20 (5000/Pkt) | E8: PKT | F8: 20 | G8: 12 | H8: AL ABDULLA TRDG DN-22834
A9: 45638 | B9: 591101840019 | C9: 45638 | D9: Stucco Putty - Jotun - 20L | E9: DRM | F9: 10 | G9: 64 | H9: AL ABDULLA TRDG DN-22834
A10: 45638 | B10: 401101840214 | C10: 45638 | D10: Olfa Blade - AB10 | E10: PKT | F10: 30 | G10: 12 | H10: AL ABDULLA TRDG DN-22834
A11: 45638 | B11: 591101840019 | C11: 45638 | D11: Stucco Putty - Jotun - 20L | E11: DRM | F11: 10 | G11: 64 | H11: AL BAHAR DN-15307
A12: 45638 | B12: 401101840025 | C12: 45638 | D12: Screw 3" x8 black - (250/300 Pkt) | E12: PKT | F12: 200 | G12: 17.5 | H12: AL BAHAR DN-15307
A13: 45638 | B13: 091101840002 | C13: 45638 | D13: Grinding Disk 4.5" (CUTTING DISC 4.5") | E13: PCS | F13: 100 | G13: 3.5 | H13: AL BAHAR DN-15307
... A1228: 45294 | B1228: 401101620001 | C1228: 45294 | D1228: Fibre Board (MDF) 4x8x 3mm - MD03 /HAVING MORTHAN 2 ITEM NO | E1228: SHT | F1228: 500 | G1228: 10.5 | H1228: BBMC DN-24200011

Sheet MAIN WITH ITEM CODE 1
A1: DATE | B1: ITEM CODE | C1: ITEM DESCRIPTION | D1: UOM | E1: COST | F1: D/N NO | G1: CATEGORY
A2: 45638 | B2: 401101840025 | C2: Screw 3" x8 black - (250/300 Pkt) | D2: PKT | E2: 17.5 | F2: AL ABDULLA TRDG DN-22834 | G2: CARPENTER
A3: 45638 | B3: 091101840002 | C3: Grinding Disk 4.5" (CUTTING DISC 4.5") | D3: PCS | E3: 3.5 | F3: AL ABDULLA TRDG DN-22834 | G3: STEEL FABRICATION
A4: 45638 | B4: 401101840296 | C4: Abrasive paper (SAND PAPER) - 320 Korea | D4: Pcs | E4: 0.9 | F4: AL ABDULLA TRDG DN-22834 | G4: PAINTER
A5: 45638 | B5: 401101840019 | C5: Mini paint roller 4" Refiller | D5: PCS | E5: 1.5 | F5: AL ABDULLA TRDG DN-22834 | G5: PAINTER
A6: 45638 | B6: 401101840006 | C6: Hand brush 2" | D6: PCS | E6: 3.5 | F6: AL ABDULLA TRDG DN-22834 | G6: PAINTER
A7: 45638 | B7: 401101840131 | C7: Hand Brush Petta - 1" - Oryx | D7: PCS | E7: 3 | F7: AL ABDULLA TRDG DN-22834 | G7: PAINTER
A8: 45638 | B8: 581101840004 | C8: Brad Nail Billionaire - F 20 (5000/Pkt) | D8: PKT | E8: 12 | F8: AL ABDULLA TRDG DN-22834 | G8: CARPENTER
A9: 45638 | B9: 591101840019 | C9: Stucco Putty - Jotun - 20L | D9: DRM | E9: 64 | F9: AL ABDULLA TRDG DN-22834 | G9: PAINTER
A10: 45638 | B10: 401101840214 | C10: Olfa Blade - AB10 | D10: PKT | E10: 12 | F10: AL ABDULLA TRDG DN-22834 | G10: GENERAL WORK
A11: 45636 | B11: 401101840248 | C11: Jotun Fenomastic Matt White Water Base - Emulsion | D11: DRM | E11: 275 | F11: AL ABDUULLA DN NO- 22831 | G11: PAINTER
A12: 45636 | B12: 401101840266 | C12: Easy Colour Blue 717 - 250Ml | D12: BTL | E12: 42 | F12: AL ABDUULLA DN NO- 22831 | G12: PAINTER
A13: 45636 | B13: 401101840092 | C13: Abrasive paper (SAND PAPER) - 180 Korea | D13: SHT | E13: 0.9 | F13: AL ABDUULLA DN NO- 22831 | G13: PAINTER
... A245: 45300 | B245: 127 | C245: EPS FOAM BLOCK 500X120X100CM D16-1 | D245: BLOCK | E245: 1100 | F245: NPPF | G245: FOAM AND DESIGN WORK

Sheet MAIN WITHOUT ITEM CODE 0
A1: DATE | B1: ITEM CODE | C1: DATE | D1: ITEM DESCRIPTION | E1: UOM | F1: DELIVERY | G1: COST | H1: D/N NO AND R/V NO
A2: 45638 | B2: 1193 | C2: 45638 | D2: Measuring Tape - 5 mtr | E2: Pcs | F2: 6 | G2: 0 | H2: AL ABDULLA TRDG DN-22834
A3: 45638 | B3: 1190 | C3: 45638 | D3: Knipex Cutter - Germany | E3: Pcs | F3: 10 | G3: 0 | H3: AL ABDULLA TRDG DN-22834
A4: 45638 | B4: 1354 | C4: 45638 | D4: NYLONE ROPE 10MM - 100MTR | E4: RL | F4: 5 | G4: 0 | H4: AL BAHAR DN-15307
A5: 45638 | B5: 1193 | C5: 45638 | D5: Measuring Tape - 5 mtr | E5: Pcs | F5: 6 | G5: 0 | H5: AL BAHAR DN-15307
A6: 45636 | B6: 1122 | C6: 45636 | D6: Safety Glass Black | E6: Pcs | F6: 12 | G6: 0 | H6: AL ABDUULLA DN NO- 22831
A7: 45636 | B7: 1122 | C7: 45636 | D7: Safety Glass Black | E7: Pcs | F7: 12 | G7: 0 | H7: AL BAHAR DN NO-16043
A8: 45631 | B8: 1455 | C8: 45631 | D8: ROBUSTLINE DOOR HINGES 4" | E8: PCS | F8: 10 | G8: 0 | H8: AL ABDULLA TRDG DN-22817
A9: 45631 | B9: 1455 | C9: 45631 | D9: ROBUSTLINE DOOR HINGES 4" | E9: PCS | F9: 10 | G9: 0 | H9: AL BAHAR DN-16027
A10: 45631 | B10: 1190 | C10: 45631 | D10: Knipex Cutter - Germany | E10: Pcs | F10: 10 | G10: 0 | H10: AL BAHAR DN-16027
A11: 45629 | B11: 1164 | C11: 45629 | D11: Water filter | E11: Pcs | F11: 20 | G11: 0 | H11: AL BAHAR DN NO- 16023
A12: 45629 | B12: 1372 | C12: 45629 | D12: SCRAPER SET SMALL | E12: SET | F12: 15 | G12: 0 | H12: AL BAHAR DN NO- 16023
A13: 45628 | B13: 1164 | C13: 45628 | D13: Water filter | E13: Pcs | F13: 20 | G13: 0 | H13: AL ABDULLA TRDG DN-22811
... A170: 45302 | B170: 1164 | C170: 45302 | D170: Water filter | E170: Pcs | F170: 50 | G170: 0 | H170: RED PHOENIX DN-4477

Sheet MAIN WITHOUT ITEM CODE 1
A1: DATE | B1: ITEM CODE | C1: ITEM DESCRIPTION | D1: UOM | E1: D/N NO | F1: COST
A2: 45638 | B2: 1193 | C2: =IFERROR(VLOOKUP(B2,'MAIN WITHOUT ITEM CODE 0'!$B$2:$H$170,3,0),0) -> Measuring Tape - 5 mtr | D2: =IFERROR(VLOOKUP(B2,'MAIN WITHOUT ITEM CODE 0'!$B$2:$H$170,4,0),0) -> Pcs | E2: =IFERROR(VLOOKUP(B2,'MAIN WITHOUT ITEM CODE 0'!$B$2:$H$170,7,0),0) -> AL ABDULLA TRDG DN-22834
A3: 45638 | B3: 1190 | C3: =IFERROR(VLOOKUP(B3,'MAIN WITHOUT ITEM CODE 0'!$B$2:$H$170,3,0),0) -> Knipex Cutter - Germany | D3: =IFERROR(VLOOKUP(B3,'MAIN WITHOUT ITEM CODE 0'!$B$2:$H$170,4,0),0) -> Pcs | E3: =IFERROR(VLOOKUP(B3,'MAIN WITHOUT ITEM CODE 0'!$B$2:$H$170,7,0),0) -> AL ABDULLA TRDG DN-22834
A4: 45638 | B4: 1354 | C4: =IFERROR(VLOOKUP(B4,'MAIN WITHOUT ITEM CODE 0'!$B$2:$H$170,3,0),0) -> NYLONE ROPE 10MM - 100MTR | D4: =IFERROR(VLOOKUP(B4,'MAIN WITHOUT ITEM CODE 0'!$B$2:$H$170,4,0),0) -> RL | E4: =IFERROR(VLOOKUP(B4,'MAIN WITHOUT ITEM CODE 0'!$B$2:$H$170,7,0),0) -> AL BAHAR DN-15307
A5: 45636 | B5: 1122 | C5: =IFERROR(VLOOKUP(B5,'MAIN WITHOUT ITEM CODE 0'!$B$2:$H$170,3,0),0) -> Safety Glass Black | D5: =IFERROR(VLOOKUP(B5,'MAIN WITHOUT ITEM CODE 0'!$B$2:$H$170,4,0),0) -> Pcs | E5: =IFERROR(VLOOKUP(B5,'MAIN WITHOUT ITEM CODE 0'!$B$2:$H$170,7,0),0) -> AL ABDUULLA DN NO- 22831
A6: 45631 | B6: 1455 | C6: =IFERROR(VLOOKUP(B6,'MAIN WITHOUT ITEM CODE 0'!$B$2:$H$170,3,0),0) -> ROBUSTLINE DOOR HINGES 4" | D6: =IFERROR(VLOOKUP(B6,'MAIN WITHOUT ITEM CODE 0'!$B$2:$H$170,4,0),0) -> PCS | E6: =IFERROR(VLOOKUP(B6,'MAIN WITHOUT ITEM CODE 0'!$B$2:$H$170,7,0),0) -> AL ABDULLA TRDG DN-22817
A7: 45629 | B7: 1164 | C7: =IFERROR(VLOOKUP(B7,'MAIN WITHOUT ITEM CODE 0'!$B$2:$H$170,3,0),0) -> Water filter | D7: =IFERROR(VLOOKUP(B7,'MAIN WITHOUT ITEM CODE 0'!$B$2:$H$170,4,0),0) -> Pcs | E7: =IFERROR(VLOOKUP(B7,'MAIN WITHOUT ITEM CODE 0'!$B$2:$H$170,7,0),0) -> AL BAHAR DN NO- 16023
A8: 45629 | B8: 1372 | C8: =IFERROR(VLOOKUP(B8,'MAIN WITHOUT ITEM CODE 0'!$B$2:$H$170,3,0),0) -> SCRAPER SET SMALL | D8: =IFERROR(VLOOKUP(B8,'MAIN WITHOUT ITEM CODE 0'!$B$2:$H$170,4,0),0) -> SET | E8: =IFERROR(VLOOKUP(B8,'MAIN WITHOUT ITEM CODE 0'!$B$2:$H$170,7,0),0) -> AL BAHAR DN NO- 16023
A9: 45624 | B9: 1336 | C9: =IFERROR(VLOOKUP(B9,'MAIN WITHOUT ITEM CODE 0'!$B$2:$H$170,3,0),0) -> TARPAULIN SHEET 40X40 | D9: =IFERROR(VLOOKUP(B9,'MAIN WITHOUT ITEM CODE 0'!$B$2:$H$170,4,0),0) -> SHT | E9: =IFERROR(VLOOKUP(B9,'MAIN WITHOUT ITEM CODE 0'!$B$2:$H$170,7,0),0) -> AL BAHAR DN-16016
A10: 45619 | B10: 1166 | C10: =IFERROR(VLOOKUP(B10,'MAIN WITHOUT ITEM CODE 0'!$B$2:$H$170,3,0),0) -> Welding Electrode E6013 | D10: =IFERROR(VLOOKUP(B10,'MAIN WITHOUT ITEM CODE 0'!$B$2:$H$170,4,0),0) -> Pkt | E10: =IFERROR(VLOOKUP(B10,'MAIN WITHOUT ITEM CODE 0'!$B$2:$H$170,7,0),0) -> AL ABDULLA TRDG DN-22140 | F10: 14
A11: 45619 | B11: 1149 | C11: =IFERROR(VLOOKUP(B11,'MAIN WITHOUT ITEM CODE 0'!$B$2:$H$170,3,0),0) -> Steel Angle 2 Hole 30x30x15mm | D11: =IFERROR(VLOOKUP(B11,'MAIN WITHOUT ITEM CODE 0'!$B$2:$H$170,4,0),0) -> Pcs | E11: =IFERROR(VLOOKUP(B11,'MAIN WITHOUT ITEM CODE 0'!$B$2:$H$170,7,0),0) -> AL ABDULLA TRDG DN-22140
A12: 45614 | B12: 1024 | C12: =IFERROR(VLOOKUP(B12,'MAIN WITHOUT ITEM CODE 0'!$B$2:$H$170,3,0),0) -> Binding wire gauge-16 | D12: =IFERROR(VLOOKUP(B12,'MAIN WITHOUT ITEM CODE 0'!$B$2:$H$170,4,0),0) -> Roll | E12: =IFERROR(VLOOKUP(B12,'MAIN WITHOUT ITEM CODE 0'!$B$2:$H$170,7,0),0) -> AL BAHAR DN-15246
A13: 45608 | B13: 1465 | C13: =IFERROR(VLOOKUP(B13,'MAIN WITHOUT ITEM CODE 0'!$B$2:$H$170,3,0),0) -> PVC COATED WIRE ROPE 2MM | D13: =IFERROR(VLOOKUP(B13,'MAIN WITHOUT ITEM CODE 0'!$B$2:$H$170,4,0),0) -> PCS | E13: =IFERROR(VLOOKUP(B13,'MAIN WITHOUT ITEM CODE 0'!$B$2:$H$170,7,0),0) -> AL BAHAR DN NO- 15237
A14: 45606 | B14: 1175 | C14: =IFERROR(VLOOKUP(B14,'MAIN WITHOUT ITEM CODE 0'!$B$2:$H$170,3,0),0) -> Floor Cleaning Mope | D14: =IFERROR(VLOOKUP(B14,'MAIN WITHOUT ITEM CODE 0'!$B$2:$H$170,4,0),0) -> Pcs | E14: =IFERROR(VLOOKUP(B14,'MAIN WITHOUT ITEM CODE 0'!$B$2:$H$170,7,0),0) -> AL ABDULLA TRDG DN-22105
A15: 45605 | B15: 1059 | C15: =IFERROR(VLOOKUP(B15,'MAIN WITHOUT ITEM CODE 0'!$B$2:$H$170,3,0),0) -> Ear plug | D15: =IFERROR(VLOOKUP(B15,'MAIN WITHOUT ITEM CODE 0'!$B$2:$H$170,4,0),0) -> box | E15: =IFERROR(VLOOKUP(B15,'MAIN WITHOUT ITEM CODE 0'!$B$2:$H$170,7,0),0) -> AL ABDULLA DN NO - 22103
A16: 45605 | B16: 1082 | C16: =IFERROR(VLOOKUP(B16,'MAIN WITHOUT ITEM CODE 0'!$B$2:$H$170,3,0),0) -> Hammer (Small) - Patta | D16: =IFERROR(VLOOKUP(B16,'MAIN WITHOUT ITEM CODE 0'!$B$2:$H$170,4,0),0) -> Nos | E16: =IFERROR(VLOOKUP(B16,'MAIN WITHOUT ITEM CODE 0'!$B$2:$H$170,7,0),0) -> AL ABDULLA DN NO - 22103
A17: 45605 | B17: 1142 | C17: =IFERROR(VLOOKUP(B17,'MAIN WITHOUT ITEM CODE 0'!$B$2:$H$170,3,0),0) -> Socket 3/8 | D17: =IFERROR(VLOOKUP(B17,'MAIN WITHOUT ITEM CODE 0'!$B$2:$H$170,4,0),0) -> PCS | E17: =IFERROR(VLOOKUP(B17,'MAIN WITHOUT ITEM CODE 0'!$B$2:$H$170,7,0),0) -> AL BAHAR DN-15229
A18: 45602 | B18: 1396 | C18: =IFERROR(VLOOKUP(B18,'MAIN WITHOUT ITEM CODE 0'!$B$2:$H$170,3,0),0) -> WELDING CABLE 70MM | D18: =IFERROR(VLOOKUP(B18,'MAIN WITHOUT ITEM CODE 0'!$B$2:$H$170,4,0),0) -> MTR | E18: =IFERROR(VLOOKUP(B18,'MAIN WITHOUT ITEM CODE 0'!$B$2:$H$170,7,0),0) -> AL BAHAR DN NO- 15223
A19: 45602 | B19: 1192 | C19: =IFERROR(VLOOKUP(B19,'MAIN WITHOUT ITEM CODE 0'!$B$2:$H$170,3,0),0) -> Gypsum powder - 30 kg | D19: =IFERROR(VLOOKUP(B19,'MAIN WITHOUT ITEM CODE 0'!$B$2:$H$170,4,0),0) -> Nos | E19: =IFERROR(VLOOKUP(B19,'MAIN WITHOUT ITEM CODE 0'!$B$2:$H$170,7,0),0) -> AL BAHAR DN NO- 15223
A20: 45599 | B20: 1419 | C20: =IFERROR(VLOOKUP(B20,'MAIN WITHOUT ITEM CODE 0'!$B$2:$H$170,3,0),0) -> STEEL HAND BRUSH | D20: =IFERROR(VLOOKUP(B20,'MAIN WITHOUT ITEM CODE 0'!$B$2:$H$170,4,0),0) -> PCS | E20: =IFERROR(VLOOKUP(B20,'MAIN WITHOUT ITEM CODE 0'!$B$2:$H$170,7,0),0) -> AL ABDULLA DN NO-21986
A21: 45594 | B21: 1123 | C21: =IFERROR(VLOOKUP(B21,'MAIN WITHOUT ITEM CODE 0'!$B$2:$H$170,3,0),0) -> Safety Glass White | D21: =IFERROR(VLOOKUP(B21,'MAIN WITHOUT ITEM CODE 0'!$B$2:$H$170,4,0),0) -> Pcs | E21: =IFERROR(VLOOKUP(B21,'MAIN WITHOUT ITEM CODE 0'!$B$2:$H$170,7,0),0) -> AL ABDULLA TRDG DN-21971
A22: 45594 | B22: 1079 | C22: =IFERROR(VLOOKUP(B22,'MAIN WITHOUT ITEM CODE 0'!$B$2:$H$170,3,0),0) -> Gypsom Power | D22: =IFERROR(VLOOKUP(B22,'MAIN WITHOUT ITEM CODE 0'!$B$2:$H$170,4,0),0) -> Nos | E22: =IFERROR(VLOOKUP(B22,'MAIN WITHOUT ITEM CODE 0'!$B$2:$H$170,7,0),0) -> AL ABDULLA TRDG DN-21971
... A60: 45319 | B60: 1446 | C60: =IFERROR(VLOOKUP(B60,'MAIN WITHOUT ITEM CODE 0'!$B$2:$H$170,3,0),0) -> Fix Bolt 12mm | D60: =IFERROR(VLOOKUP(B60,'MAIN WITHOUT ITEM CODE 0'!$B$2:$H$170,4,0),0) -> PKT | E60: =IFERROR(VLOOKUP(B60,'MAIN WITHOUT ITEM CODE 0'!$B$2:$H$170,7,0),0) -> AL BAHAR DN-13606

Sheet COST 0
A1: CODE | B1: DESCRIPTION | C1: COST PRICE
A2: 010020020001 | B2: ALESSANDRO - ALBUM 228 -35X45 IVY SH 50-100+C | C2: 1479.32
A3: 010050060001 | B3: AYMAN SYR ALBUM - COL . Assort FLW -W/CASE-0 | C3: 299.96
A4: 010060070001 | B4: BIELLE BROWN FIORINO F7 (35X35) | C4: 287.89
A5: 010060070002 | B5: BIELLE P2 BLU F2 VERDE BLACK & RED | C5: 98
A6: 010060070003 | B6: C 100 ITALY LEATHER IVORY PAGES | C6: 811.59
A7: 010060070004 | B7: BIELLE ALBUM - IVORY FIORINO F1 - 35 X 35 | C7: 278.66
A8: 010060070005 | B8: BIELLE C2 - BLUE JEANS LEATHER IVORY PAGES | C8: 461.35
A9: 010060070006 | B9: BIELLE ALBUM P 2 VERDE | C9: 98
A10: 010060070007 | B10: BIELLE ALBUM P 2 BORO 5 | C10: 98
A11: 010060070008 | B11: BIELLE ALBUM F5 WALNUT FIORINO 35X35 40SH IVY | C11: 284.24
A12: 010060070009 | B12: BIELLE ALBUM - C127 GREEN OSTR IVY 35X35-LEA | C12: 1755.81
A13: 010060070010 | B13: BIELLE ALBUM - C128 WHITE COCCO IVY 35X35-LEA | C13: 1755.81
... A8305: 741101840001 | B8305: Wooden Legs For Chair And Table | C8305: 91.61

Sheet MAIN 0
A1: CODE | B1: DESCRIPTION | C1: COST PRICE
A2: 010020020001 | B2: ALESSANDRO - ALBUM 228 -35X45 IVY SH 50-100+C | C2: 1479.32
A3: 010050060001 | B3: AYMAN SYR ALBUM - COL . Assort FLW -W/CASE-0 | C3: 299.96
A4: 010060070001 | B4: BIELLE BROWN FIORINO F7 (35X35) | C4: 287.89
A5: 010060070002 | B5: BIELLE P2 BLU F2 VERDE BLACK & RED | C5: 98
A6: 010060070003 | B6: C 100 ITALY LEATHER IVORY PAGES | C6: 811.59
A7: 010060070004 | B7: BIELLE ALBUM - IVORY FIORINO F1 - 35 X 35 | C7: 278.66
A8: 010060070005 | B8: BIELLE C2 - BLUE JEANS LEATHER IVORY PAGES | C8: 461.35
A9: 010060070006 | B9: BIELLE ALBUM P 2 VERDE | C9: 98
A10: 010060070007 | B10: BIELLE ALBUM P 2 BORO 5 | C10: 98
A11: 010060070008 | B11: BIELLE ALBUM F5 WALNUT FIORINO 35X35 40SH IVY | C11: 284.24
A12: 010060070009 | B12: BIELLE ALBUM - C127 GREEN OSTR IVY 35X35-LEA | C12: 1755.81
A13: 010060070010 | B13: BIELLE ALBUM - C128 WHITE COCCO IVY 35X35-LEA | C13: 1755.81
... A6861: 741101840001 | B6861: Wooden Legs For Chair And Table | C6861: 91.61

Sheet STEEL MAIN
A1: DATE | B1: ITEM CODE | C1: ITEM DESCRIPTION | D1: UOM | E1: DELIVERY | F1: D/N NO AND R/V NO | G1: UNIT PRICE
A2: 45636 | B2: 401101840397 | C2: STEEL TUBE 30X30X1.5MM | D2: Pcs | E2: 50 | F2: QATAR STEEL DN NO- 74734 INV NO-120808 | G2: 22.5
A3: 45634 | B3: 401101840496 | C3: Rec.Angle Tube 40x20x1.5mm | D3: PCS | E3: 150 | F3: QATAR STEEL DN-74680 | G3: 22
A4: 45634 | B4: 401101840413 | C4: STEEL TUBE 40X40X1.5MM | D4: Pcs | E4: 50 | F4: QATAR STEEL DN-74680 | G4: 29.5
A5: 45630 | B5: 401101840442 | C5: STEEL TUBE 16X16X1.5MM | D5: Pcs | E5: 150 | F5: QATAR STEEL DN-24604 | G5: 12.25
A6: 45620 | B6: 401101840396 | C6: STEEL TUBE 25X25X1.5MM | D6: Pcs | E6: 200 | F6: QATAR STEEL DN-76442 | G6: 20
A7: 45612 | B7: 401101840397 | C7: STEEL TUBE 30X30X1.5MM | D7: Pcs | E7: 159 | F7: QATAR STEEL DN-76178 | G7: 22.5
A8: 45612 | B8: 401101840396 | C8: STEEL TUBE 25X25X1.5MM | D8: Pcs | E8: 520 | F8: QATAR STEEL DN-76178 | G8: 20
A9: 45612 | B9: 401101840493 | C9: STEEL TUBE 19X19X1.5MM | D9: PCS | E9: 100 | F9: QATAR STEEL DN-76178 | G9: 14.9
A10: 45610 | B10: 401101840396 | C10: STEEL TUBE 25X25X1.5MM | D10: Pcs | E10: 180 | F10: QATAR STEEL DN NO-76154 INV NO-119842 | G10: 20
A11: 45610 | B11: 401101840397 | C11: STEEL TUBE 30X30X1.5MM | D11: Pcs | E11: 121 | F11: QATAR STEEL DN NO-76154 INV NO-119842 | G11: 22.5
A12: 45607 | B12: 401101840413 | C12: STEEL TUBE 40X40X1.5MM | D12: Pcs | E12: 100 | F12: QATAR STEEL DN-76048 | G12: 29.5
A13: 45603 | B13: 401101840413 | C13: STEEL TUBE 40X40X1.5MM | D13: Pcs | E13: 250 | F13: QATAR STEEL DN-76925 | G13: 29.5
... A56: 45299 | B56: 401101840397 | C56: STEEL TUBE 30X30X1.5MM | D56: Pcs | E56: 70 | F56: QATAR STEEL DN-67560 | G56: 22.5
